Workbook

Sheet Léeme
A1: Flota de drones · Ucrania (conjunto de datos SINTÉTICO)
A3: Aviso importante
A4: Los 500 registros de este libro fueron generados por simulación estadística (numpy, semilla 2026).
A5: NO proceden de fuentes de inteligencia, ni describen unidades, sistemas ni operaciones reales.
A6: Los nombres de modelo son ficticios y las cifras son plausibles pero inventadas. Uso exclusivo:
A7: práctica de análisis exploratorio de datos, dashboards y visualización.
A9: Contenido del libro
A10: Datos · 500 aeronaves, una por fila, 15 columnas (14 de datos + 1 calculada con fórmula).
A11: Resumen · indicadores y tablas agregadas por clase, sector e interferencia GNSS.
A12: Todas las celdas del resumen son fórmulas vivas sobre la hoja Datos:
A13: si filtras, editas o amplías los datos, el resumen se recalcula solo.
A15: Diccionario de datos
A17: Columna | B17: Tipo | C17: Unidad | D17: Descripción
A18: ID_Dron | B18: Texto | C18: — | D18: Identificador único de la aeronave (DRN_0000 … DRN_0499).
A19: Modelo | B19: Texto | C19: — | D19: Denominación ficticia del modelo; 14 modelos repartidos entre las 6 clases.
A20: Clase | B20: Texto | C20: — | D20: Reconocimiento ISR, FPV de ataque, Bombardero nocturno, Ala fija largo alcance, Interceptor antidrón, Logístico.
A21: Origen | B21: Texto | C21: — | D21: País de fabricación declarado (6 categorías).
A22: Sector_Frente | B22: Texto | C22: — | D22: Zona de despliegue (6 sectores + Retaguardia).
A23: Fecha_Alta | B23: Fecha | C23: AAAA-MM-DD | D23: Entrada en servicio de la unidad; entre 2025-01-15 y 2026-05-29.
A24: Autonomia_Min | B24: Número | C24: minutos | D24: Tiempo de vuelo nominal por salida.
A25: Alcance_km | B25: Número | C25: km | D25: Radio de operación nominal.
A26: Misiones_Mensuales | B26: Entero | C26: misiones/mes | D26: Ritmo medio de salidas mensuales.
A27: Horas_Vuelo_Acumuladas | B27: Número | C27: horas | D27: Horas totales desde el alta; función de misiones, autonomía y meses en servicio.
A28: Tasa_Exito_Mision_Pct | B28: Número | C28: % | D28: Porcentaje de misiones completadas; penalizado por la interferencia GNSS.
... A32: Coste_por_Mision_USD | B32: Fórmula | C32: USD/misión | D32: Calculada en la hoja Datos: coste unitario ÷ misiones mensuales.
A35: Relaciones incorporadas a la simulación (útiles para validar el EDA)
A36: · La energía del ritmo operativo: las horas de vuelo crecen con misiones × meses en servicio × autonomía.
A37: · La interferencia GNSS reduce la tasa de éxito (Baja ≈ 73% frente a Muy Alta ≈ 57% de media).
A38: · Donetsk y Zaporiyia concentran la interferencia alta, y con ella una mayor proporción de pérdidas.
A39: · El FPV de ataque es la clase más barata y con mayor riesgo; el ala fija, la más cara y de mayor alcance.

Sheet Datos
A1: ID_Dron | B1: Modelo | C1: Clase | D1: Origen | E1: Sector_Frente | F1: Fecha_Alta | G1: Autonomia_Min | H1: Alcance_km | I1: Misiones_Mensuales | J1: Horas_Vuelo_Acumuladas | K1: Tasa_Exito_Mision_Pct | L1: Interferencia_GNSS | M1: Coste_Unitario_USD | N1: Estado | O1: Coste_por_Mision_USD
A2: DRN_0000 | B2: Vigía-X4 | C2: Reconocimiento ISR | D2: Polonia | E2: Járkiv | F2: 2025-04-04 | G2: 52.3 | H2: 23.4 | I2: 20 | J2: 255.9 | K2: 81.3 | L2: Alta | M2: 3154 | N2: Operativo | O2: =IFERROR(M2/I2,"") -> 157.7
A3: DRN_0001 | B3: Nocturno-H8 | C3: Bombardero nocturno | D3: Ucrania | E3: Donetsk | F3: 2026-02-17 | G3: 38.7 | H3: 14.2 | I3: 10 | J3: 33.3 | K3: 66.5 | L3: Alta | M3: 23832 | N3: Perdido | O3: =IFERROR(M3/I3,"") -> 2383.2
A4: DRN_0002 | B4: Osa-7 | C4: FPV de ataque | D4: China (comercial) | E4: Sumy | F4: 2026-03-18 | G4: 13.4 | H4: 9.2 | I4: 10 | J4: 9.7 | K4: 61.7 | L4: Baja | M4: 654 | N4: Operativo | O4: =IFERROR(M4/I4,"") -> 65.4
A5: DRN_0003 | B5: Kvadro-FPV Mk3 | C5: FPV de ataque | D5: Ucrania | E5: Jersón | F5: 2025-11-14 | G5: 11.8 | H5: 9.8 | I5: 9 | J5: 15.4 | K5: 58.2 | L5: Baja | M5: 634 | N5: Operativo | O5: =IFERROR(M5/I5,"") -> 70.444444
A6: DRN_0004 | B6: Kvadro-FPV Mk5 | C6: FPV de ataque | D6: Ucrania | E6: Donetsk | F6: 2026-04-18 | G6: 16.1 | H6: 9.5 | I6: 3 | J6: 2.5 | K6: 44 | L6: Alta | M6: 498 | N6: Operativo | O6: =IFERROR(M6/I6,"") -> 166
A7: DRN_0005 | B7: Sokil-INT3 | C7: Interceptor antidrón | D7: Ucrania | E7: Lugansk | F7: 2025-11-26 | G7: 26.9 | H7: 42.8 | I7: 7 | J7: 28.8 | K7: 42.4 | L7: Alta | M7: 12034 | N7: Operativo | O7: =IFERROR(M7/I7,"") -> 1719.1429
A8: DRN_0006 | B8: Mula-L4 | C8: Logístico | D8: China (comercial) | E8: Járkiv | F8: 2025-09-03 | G8: 38.2 | H8: 13.6 | I8: 18 | J8: 160.7 | K8: 83.1 | L8: Media | M8: 7876 | N8: Operativo | O8: =IFERROR(M8/I8,"") -> 437.55556
A9: DRN_0007 | B9: Vigía-X2 | C9: Reconocimiento ISR | D9: China (comercial) | E9: Zaporiyia | F9: 2025-03-13 | G9: 42.4 | H9: 14.9 | I9: 18 | J9: 225.5 | K9: 68.3 | L9: Muy Alta | M9: 3643 | N9: Operativo | O9: =IFERROR(M9/I9,"") -> 202.38889
A10: DRN_0008 | B10: Nocturno-H6 | C10: Bombardero nocturno | D10: China (comercial) | E10: Járkiv | F10: 2025-08-03 | G10: 38.5 | H10: 27.4 | I10: 14 | J10: 108 | K10: 70.5 | L10: Media | M10: 31928 | N10: Operativo | O10: =IFERROR(M10/I10,"") -> 2280.5714
A11: DRN_0009 | B11: Kvadro-FPV Mk3 | C11: FPV de ataque | D11: China (comercial) | E11: Járkiv | F11: 2026-03-26 | G11: 17.1 | H11: 10.7 | I11: 24 | J11: 29.3 | K11: 60.7 | L11: Media | M11: 567 | N11: Perdido | O11: =IFERROR(M11/I11,"") -> 23.625
A12: DRN_0010 | B12: Mula-L4 | C12: Logístico | D12: China (comercial) | E12: Retaguardia | F12: 2026-02-04 | G12: 31.5 | H12: 34.1 | I12: 7 | J12: 18.8 | K12: 85.7 | L12: Media | M12: 9908 | N12: Operativo | O12: =IFERROR(M12/I12,"") -> 1415.4286
A13: DRN_0011 | B13: Mula-L2 | C13: Logístico | D13: China (comercial) | E13: Jersón | F13: 2025-08-01 | G13: 37.4 | H13: 31.6 | I13: 27 | J13: 173.6 | K13: 80.4 | L13: Alta | M13: 6699 | N13: Operativo | O13: =IFERROR(M13/I13,"") -> 248.11111
... A501: DRN_0499 | B501: Otarnia-R1 | C501: Reconocimiento ISR | D501: Polonia | E501: Donetsk | F501: 2025-05-01 | G501: 76.7 | H501: 13.5 | I501: 6 | J501: 93.5 | K501: 70.6 | L501: Alta | M501: 2687 | N501: En mantenimiento | O501: =IFERROR(M501/I501,"") -> 447.83333

Sheet Resumen
A1: Resumen de la flota
A2: Todas las cifras son fórmulas sobre la hoja Datos (rango A2:O501).
A4: Indicadores generales
A5: Aeronaves registradas | B5: =COUNTA(Datos!A2:A501) -> 500
A6: Operativas | B6: =COUNTIF(Datos!N2:N501,"Operativo") -> 262
A7: Perdidas | B7: =COUNTIF(Datos!N2:N501,"Perdido") -> 123
A8: Tasa de pérdida | B8: =IFERROR(COUNTIF(Datos!N2:N501,"Perdido")/COUNTA(Datos!A2:A501),"") -> 0.246
A9: Misiones mensuales (total) | B9: =SUM(Datos!I2:I501) -> 8096
A10: Horas de vuelo acumuladas | B10: =SUM(Datos!J2:J501) -> 71137.3
A11: Tasa de éxito media | B11: =IFERROR(AVERAGE(Datos!K2:K501)/100,"") -> 0.66418
A12: Valor de reposición de la flota | B12: =SUM(Datos!M2:M501) -> 8509494
A13: Coste medio por misión | B13: =IFERROR(SUM(Datos!M2:M501)/SUM(Datos!I2:I501),"") -> 1051.0739
A16: Por clase de dron
A17: Clase | B17: Unidades | C17: % flota | D17: Misiones/mes | E17: Éxito medio | F17: Coste unitario medio | G17: Perdidas | H17: % perdidas
A18: Ala fija largo alcance | B18: =COUNTIF(Datos!$C$2:$C$501,$A18) -> 30 | C18: =IFERROR(B18/COUNTA(Datos!$A$2:$A$501),"") -> 0.06 | D18: =SUMIF(Datos!$C$2:$C$501,$A18,Datos!$I$2:$I$501) -> 438 | E18: =IFERROR(AVERAGEIF(Datos!$C$2:$C$501,$A18,Datos!$K$2:$K$501)/100,"") -> 0.70333333 | F18: =IFERROR(AVERAGEIF(Datos!$C$2:$C$501,$A18,Datos!$M$2:$M$501),"") -> 172036.67 | G18: =COUNTIFS(Datos!$C$2:$C$501,$A18,Datos!$N$2:$N$501,"Perdido") -> 3 | H18: =IFERROR(G18/B18,"") -> 0.1
A19: Bombardero nocturno | B19: =COUNTIF(Datos!$C$2:$C$501,$A19) -> 76 | C19: =IFERROR(B19/COUNTA(Datos!$A$2:$A$501),"") -> 0.152 | D19: =SUMIF(Datos!$C$2:$C$501,$A19,Datos!$I$2:$I$501) -> 967 | E19: =IFERROR(AVERAGEIF(Datos!$C$2:$C$501,$A19,Datos!$K$2:$K$501)/100,"") -> 0.65927632 | F19: =IFERROR(AVERAGEIF(Datos!$C$2:$C$501,$A19,Datos!$M$2:$M$501),"") -> 22042.961 | G19: =COUNTIFS(Datos!$C$2:$C$501,$A19,Datos!$N$2:$N$501,"Perdido") -> 14 | H19: =IFERROR(G19/B19,"") -> 0.18421053
A20: FPV de ataque | B20: =COUNTIF(Datos!$C$2:$C$501,$A20) -> 173 | C20: =IFERROR(B20/COUNTA(Datos!$A$2:$A$501),"") -> 0.346 | D20: =SUMIF(Datos!$C$2:$C$501,$A20,Datos!$I$2:$I$501) -> 3794 | E20: =IFERROR(AVERAGEIF(Datos!$C$2:$C$501,$A20,Datos!$K$2:$K$501)/100,"") -> 0.53337572 | F20: =IFERROR(AVERAGEIF(Datos!$C$2:$C$501,$A20,Datos!$M$2:$M$501),"") -> 658.95376 | G20: =COUNTIFS(Datos!$C$2:$C$501,$A20,Datos!$N$2:$N$501,"Perdido") -> 76 | H20: =IFERROR(G20/B20,"") -> 0.43930636
A21: Interceptor antidrón | B21: =COUNTIF(Datos!$C$2:$C$501,$A21) -> 44 | C21: =IFERROR(B21/COUNTA(Datos!$A$2:$A$501),"") -> 0.088 | D21: =SUMIF(Datos!$C$2:$C$501,$A21,Datos!$I$2:$I$501) -> 541 | E21: =IFERROR(AVERAGEIF(Datos!$C$2:$C$501,$A21,Datos!$K$2:$K$501)/100,"") -> 0.57345455 | F21: =IFERROR(AVERAGEIF(Datos!$C$2:$C$501,$A21,Datos!$M$2:$M$501),"") -> 13966 | G21: =COUNTIFS(Datos!$C$2:$C$501,$A21,Datos!$N$2:$N$501,"Perdido") -> 15 | H21: =IFERROR(G21/B21,"") -> 0.34090909
A22: Logístico | B22: =COUNTIF(Datos!$C$2:$C$501,$A22) -> 69 | C22: =IFERROR(B22/COUNTA(Datos!$A$2:$A$501),"") -> 0.138 | D22: =SUMIF(Datos!$C$2:$C$501,$A22,Datos!$I$2:$I$501) -> 954 | E22: =IFERROR(AVERAGEIF(Datos!$C$2:$C$501,$A22,Datos!$K$2:$K$501)/100,"") -> 0.83995652 | F22: =IFERROR(AVERAGEIF(Datos!$C$2:$C$501,$A22,Datos!$M$2:$M$501),"") -> 8195.7391 | G22: =COUNTIFS(Datos!$C$2:$C$501,$A22,Datos!$N$2:$N$501,"Perdido") -> 5 | H22: =IFERROR(G22/B22,"") -> 0.072463768
A23: Reconocimiento ISR | B23: =COUNTIF(Datos!$C$2:$C$501,$A23) -> 108 | C23: =IFERROR(B23/COUNTA(Datos!$A$2:$A$501),"") -> 0.216 | D23: =SUMIF(Datos!$C$2:$C$501,$A23,Datos!$I$2:$I$501) -> 1402 | E23: =IFERROR(AVERAGEIF(Datos!$C$2:$C$501,$A23,Datos!$K$2:$K$501)/100,"") -> 0.79094444 | F23: =IFERROR(AVERAGEIF(Datos!$C$2:$C$501,$A23,Datos!$M$2:$M$501),"") -> 3510.3704 | G23: =COUNTIFS(Datos!$C$2:$C$501,$A23,Datos!$N$2:$N$501,"Perdido") -> 10 | H23: =IFERROR(G23/B23,"") -> 0.092592593
A24: TOTAL | B24: =SUM(B18:B23) -> 500 | C24: =SUM(C18:C23) -> 1 | D24: =SUM(D18:D23) -> 8096 | E24: =IFERROR(AVERAGE(Datos!$K$2:$K$501)/100,"") -> 0.66418 | F24: =IFERROR(AVERAGE(Datos!$M$2:$M$501),"") -> 17018.988 | G24: =SUM(G18:G23) -> 123 | H24: =IFERROR(G24/B24,"") -> 0.246
A27: Por sector del frente
A28: Sector | B28: Unidades | C28: % flota | D28: Misiones/mes | E28: Éxito medio | F28: Coste unitario medio | G28: Perdidas | H28: % perdidas
A29: Donetsk | B29: =COUNTIF(Datos!$E$2:$E$501,$A29) -> 139 | C29: =IFERROR(B29/COUNTA(Datos!$A$2:$A$501),"") -> 0.278 | D29: =SUMIF(Datos!$E$2:$E$501,$A29,Datos!$I$2:$I$501) -> 2301 | E29: =IFERROR(AVERAGEIF(Datos!$E$2:$E$501,$A29,Datos!$K$2:$K$501)/100,"") -> 0.63515827 | F29: =IFERROR(AVERAGEIF(Datos!$E$2:$E$501,$A29,Datos!$M$2:$M$501),"") -> 20102.863 | G29: =COUNTIFS(Datos!$E$2:$E$501,$A29,Datos!$N$2:$N$501,"Perdido") -> 36 | H29: =IFERROR(G29/B29,"") -> 0.25899281
A30: Jersón | B30: =COUNTIF(Datos!$E$2:$E$501,$A30) -> 72 | C30: =IFERROR(B30/COUNTA(Datos!$A$2:$A$501),"") -> 0.144 | D30: =SUMIF(Datos!$E$2:$E$501,$A30,Datos!$I$2:$I$501) -> 1192 | E30: =IFERROR(AVERAGEIF(Datos!$E$2:$E$501,$A30,Datos!$K$2:$K$501)/100,"") -> 0.64618056 | F30: =IFERROR(AVERAGEIF(Datos!$E$2:$E$501,$A30,Datos!$M$2:$M$501),"") -> 15828.444 | G30: =COUNTIFS(Datos!$E$2:$E$501,$A30,Datos!$N$2:$N$501,"Perdido") -> 24 | H30: =IFERROR(G30/B30,"") -> 0.33333333
A31: Járkiv | B31: =COUNTIF(Datos!$E$2:$E$501,$A31) -> 57 | C31: =IFERROR(B31/COUNTA(Datos!$A$2:$A$501),"") -> 0.114 | D31: =SUMIF(Datos!$E$2:$E$501,$A31,Datos!$I$2:$I$501) -> 837 | E31: =IFERROR(AVERAGEIF(Datos!$E$2:$E$501,$A31,Datos!$K$2:$K$501)/100,"") -> 0.70340351 | F31: =IFERROR(AVERAGEIF(Datos!$E$2:$E$501,$A31,Datos!$M$2:$M$501),"") -> 15038.386 | G31: =COUNTIFS(Datos!$E$2:$E$501,$A31,Datos!$N$2:$N$501,"Perdido") -> 14 | H31: =IFERROR(G31/B31,"") -> 0.24561404
A32: Lugansk | B32: =COUNTIF(Datos!$E$2:$E$501,$A32) -> 55 | C32: =IFERROR(B32/COUNTA(Datos!$A$2:$A$501),"") -> 0.11 | D32: =SUMIF(Datos!$E$2:$E$501,$A32,Datos!$I$2:$I$501) -> 923 | E32: =IFERROR(AVERAGEIF(Datos!$E$2:$E$501,$A32,Datos!$K$2:$K$501)/100,"") -> 0.69725455 | F32: =IFERROR(AVERAGEIF(Datos!$E$2:$E$501,$A32,Datos!$M$2:$M$501),"") -> 7955.5455 | G32: =COUNTIFS(Datos!$E$2:$E$501,$A32,Datos!$N$2:$N$501,"Perdido") -> 10 | H32: =IFERROR(G32/B32,"") -> 0.18181818
A33: Retaguardia | B33: =COUNTIF(Datos!$E$2:$E$501,$A33) -> 42 | C33: =IFERROR(B33/COUNTA(Datos!$A$2:$A$501),"") -> 0.084 | D33: =SUMIF(Datos!$E$2:$E$501,$A33,Datos!$I$2:$I$501) -> 628 | E33: =IFERROR(AVERAGEIF(Datos!$E$2:$E$501,$A33,Datos!$K$2:$K$501)/100,"") -> 0.71447619 | F33: =IFERROR(AVERAGEIF(Datos!$E$2:$E$501,$A33,Datos!$M$2:$M$501),"") -> 19874.048 | G33: =COUNTIFS(Datos!$E$2:$E$501,$A33,Datos!$N$2:$N$501,"Perdido") -> 9 | H33: =IFERROR(G33/B33,"") -> 0.21428571
A34: Sumy | B34: =COUNTIF(Datos!$E$2:$E$501,$A34) -> 41 | C34: =IFERROR(B34/COUNTA(Datos!$A$2:$A$501),"") -> 0.082 | D34: =SUMIF(Datos!$E$2:$E$501,$A34,Datos!$I$2:$I$501) -> 642 | E34: =IFERROR(AVERAGEIF(Datos!$E$2:$E$501,$A34,Datos!$K$2:$K$501)/100,"") -> 0.71168293 | F34: =IFERROR(AVERAGEIF(Datos!$E$2:$E$501,$A34,Datos!$M$2:$M$501),"") -> 18127.561 | G34: =COUNTIFS(Datos!$E$2:$E$501,$A34,Datos!$N$2:$N$501,"Perdido") -> 11 | H34: =IFERROR(G34/B34,"") -> 0.26829268
A35: Zaporiyia | B35: =COUNTIF(Datos!$E$2:$E$501,$A35) -> 94 | C35: =IFERROR(B35/COUNTA(Datos!$A$2:$A$501),"") -> 0.188 | D35: =SUMIF(Datos!$E$2:$E$501,$A35,Datos!$I$2:$I$501) -> 1573 | E35: =IFERROR(AVERAGEIF(Datos!$E$2:$E$501,$A35,Datos!$K$2:$K$501)/100,"") -> 0.63455319 | F35: =IFERROR(AVERAGEIF(Datos!$E$2:$E$501,$A35,Datos!$M$2:$M$501),"") -> 18115.585 | G35: =COUNTIFS(Datos!$E$2:$E$501,$A35,Datos!$N$2:$N$501,"Perdido") -> 19 | H35: =IFERROR(G35/B35,"") -> 0.20212766
A36: TOTAL | B36: =SUM(B29:B35) -> 500 | C36: =SUM(C29:C35) -> 1 | D36: =SUM(D29:D35) -> 8096 | E36: =IFERROR(AVERAGE(Datos!$K$2:$K$501)/100,"") -> 0.66418 | F36: =IFERROR(AVERAGE(Datos!$M$2:$M$501),"") -> 17018.988 | G36: =SUM(G29:G35) -> 123 | H36: =IFERROR(G36/B36,"") -> 0.246
A39: Por nivel de interferencia GNSS
A40: Interferencia GNSS | B40: Unidades | C40: % flota | D40: Misiones/mes | E40: Éxito medio | F40: Coste unitario medio | G40: Perdidas | H40: % perdidas
A41: Baja | B41: =COUNTIF(Datos!$L$2:$L$501,$A41) -> 86 | C41: =IFERROR(B41/COUNTA(Datos!$A$2:$A$501),"") -> 0.172 | D41: =SUMIF(Datos!$L$2:$L$501,$A41,Datos!$I$2:$I$501) -> 1408 | E41: =IFERROR(AVERAGEIF(Datos!$L$2:$L$501,$A41,Datos!$K$2:$K$501)/100,"") -> 0.72934884 | F41: =IFERROR(AVERAGEIF(Datos!$L$2:$L$501,$A41,Datos!$M$2:$M$501),"") -> 15248.221 | G41: =COUNTIFS(Datos!$L$2:$L$501,$A41,Datos!$N$2:$N$501,"Perdido") -> 21 | H41: =IFERROR(G41/B41,"") -> 0.24418605
A42: Media | B42: =COUNTIF(Datos!$L$2:$L$501,$A42) -> 164 | C42: =IFERROR(B42/COUNTA(Datos!$A$2:$A$501),"") -> 0.328 | D42: =SUMIF(Datos!$L$2:$L$501,$A42,Datos!$I$2:$I$501) -> 2645 | E42: =IFERROR(AVERAGEIF(Datos!$L$2:$L$501,$A42,Datos!$K$2:$K$501)/100,"") -> 0.70090244 | F42: =IFERROR(AVERAGEIF(Datos!$L$2:$L$501,$A42,Datos!$M$2:$M$501),"") -> 18688.744 | G42: =COUNTIFS(Datos!$L$2:$L$501,$A42,Datos!$N$2:$N$501,"Perdido") -> 35 | H42: =IFERROR(G42/B42,"") -> 0.21341463
A43: Alta | B43: =COUNTIF(Datos!$L$2:$L$501,$A43) -> 174 | C43: =IFERROR(B43/COUNTA(Datos!$A$2:$A$501),"") -> 0.348 | D43: =SUMIF(Datos!$L$2:$L$501,$A43,Datos!$I$2:$I$501) -> 2761 | E43: =IFERROR(AVERAGEIF(Datos!$L$2:$L$501,$A43,Datos!$K$2:$K$501)/100,"") -> 0.63908621 | F43: =IFERROR(AVERAGEIF(Datos!$L$2:$L$501,$A43,Datos!$M$2:$M$501),"") -> 18352.787 | G43: =COUNTIFS(Datos!$L$2:$L$501,$A43,Datos!$N$2:$N$501,"Perdido") -> 50 | H43: =IFERROR(G43/B43,"") -> 0.28735632
A44: Muy Alta | B44: =COUNTIF(Datos!$L$2:$L$501,$A44) -> 76 | C44: =IFERROR(B44/COUNTA(Datos!$A$2:$A$501),"") -> 0.152 | D44: =SUMIF(Datos!$L$2:$L$501,$A44,Datos!$I$2:$I$501) -> 1282 | E44: =IFERROR(AVERAGEIF(Datos!$L$2:$L$501,$A44,Datos!$K$2:$K$501)/100,"") -> 0.56864474 | F44: =IFERROR(AVERAGEIF(Datos!$L$2:$L$501,$A44,Datos!$M$2:$M$501),"") -> 12365.895 | G44: =COUNTIFS(Datos!$L$2:$L$501,$A44,Datos!$N$2:$N$501,"Perdido") -> 17 | H44: =IFERROR(G44/B44,"") -> 0.22368421
A45: TOTAL | B45: =SUM(B41:B44) -> 500 | C45: =SUM(C41:C44) -> 1 | D45: =SUM(D41:D44) -> 8096 | E45: =IFERROR(AVERAGE(Datos!$K$2:$K$501)/100,"") -> 0.66418 | F45: =IFERROR(AVERAGE(Datos!$M$2:$M$501),"") -> 17018.988 | G45: =SUM(G41:G44) -> 123 | H45: =IFERROR(G45/B45,"") -> 0.246
A48: Por origen del fabricante
A49: Origen | B49: Unidades | C49: % flota | D49: Misiones/mes | E49: Éxito medio | F49: Coste unitario medio | G49: Perdidas | H49: % perdidas
...
